<?xml version="1.0" encoding="UTF-8"?>
<testrun name="FailingSuite" project="JUnitTests" tests="1" started="0" failures="1" errors="0" ignored="0">
  <testsuite name="pack.FailingSuite.MySetup" incomplete="true">
    <failure>junit.framework.AssertionFailedError: failure in setUp
	at junit.framework.Assert.fail(Assert.java:47)
	at pack.FailingSuite$MySetup.setUp(FailingSuite.java:15)
	at junit.extensions.TestSetup$1.protect(TestSetup.java:20)
	at junit.framework.TestResult.runProtected(TestResult.java:124)
	at junit.extensions.TestSetup.run(TestSetup.java:25)
	at org.eclipse.jdt.internal.junit.runner.junit3.JUnit3TestReference.run(JUnit3TestReference.java:130)
	at org.eclipse.jdt.internal.junit.runner.TestExecution.run(TestExecution.java:38)
	at org.eclipse.jdt.internal.junit.runner.RemoteTestRunner.runTests(RemoteTestRunner.java:460)
	at org.eclipse.jdt.internal.junit.runner.RemoteTestRunner.runTests(RemoteTestRunner.java:673)
	at org.eclipse.jdt.internal.junit.runner.RemoteTestRunner.run(RemoteTestRunner.java:386)
	at org.eclipse.jdt.internal.junit.runner.RemoteTestRunner.main(RemoteTestRunner.java:196)

</failure>
    <testsuite name="pack.FailingSuite" incomplete="true">
      <testcase name="test1" classname="pack.FailingSuite" incomplete="true"/>
    </testsuite>
  </testsuite>
</testrun>
